Workbook

Sheet Data
A1: Log No | D1: Police Information
A2: HKP RN: | D2: Police Arrived Time
A3: TA Date | D3: Police NO:
A4: TA Time: | D4: AI Staff No:
A5: Location: | D5: HKP AI 到達時間:
A6: 隧道職員到達時間: | D6: HKP AI 離開時間:
A7: 隧道職員離開時間:
A11: Vehicle 1 | D11: Driver 1
A12: 車輛登記號碼 | D12: 英文名
A13: Class 類別 | D13: 中文名
A14: Make 廠名 | D14: 年齡
A15: Colour 顏色 | D15: 中文住址
A16: 車輛牌照號碼 | D16: 英文住址
A17: 期滿日期 | D17: 電話號碼
A18: 車輛載客額 | D18: 身份證號碼
A19: 事發時乘客數目 | D19: 駕駛執照號碼
A20: 損毀性質及程度 | D20: Class 類別
D21: 期滿日期
D22: 執照所載規條 (如有任何規條者)
A26: Vehicle 2 | D26: Driver 2
A27: 車輛登記號碼 | D27: 英文名
A28: Class 類別 | D28: 中文名
A29: Make 廠名 | D29: 年齡
A30: Colour 顏色 | D30: 中文住址
A31: 車輛牌照號碼 | D31: 英文住址
A32: 期滿日期 | D32: 電話號碼
A33: 車輛載客額 | D33: 身份證號碼
A34: 事發時乘客數目 | D34: 駕駛執照號碼
A35: 損毀性質及程度 | D35: Class 類別
D36: 期滿日期
D37: 執照所載規條 (如有任何規條者)
A42: Vehicle 3 | D42: Driver 3
A43: 車輛登記號碼 | D43: 英文名
A44: Class 類別 | D44: 中文名
A45: Make 廠名 | D45: 年齡
A46: Colour 顏色 | D46: 中文住址
A47: 車輛牌照號碼 | D47: 英文住址
A48: 期滿日期 | D48: 電話號碼
A49: 車輛載客額 | D49: 身份證號碼
A50: 事發時乘客數目 | D50: 駕駛執照號碼
...

Sheet P.1
A1: Pacific Infrastructure Limited
A2: EASTERN HARBOUR CROSSING | L2: EHT REF. NO.:
G3: TRAFFIC ACCIDENT REPORT | L3: EHT LOG NO.: | N3: =Data!B1 -> 0
G4: (SLIGHT / SERIOUS / FATAL) | L4: HKP RB NO. : | N4: =Data!B2 -> 0
A6: 1. DATE, TIME AND PLACE OF ACCIDENT 意外發生日期、時間及地點
A7: Date 日期 | C7: Time (Hrs.) 時期 | E7: Day of the week 星期
A9: =Data!B3 -> 0 | C9: =Data!B4 -> 0 | D9: 時 | E9: Sun 日 | F9: Mon 一 | G9: Tue 二 | H9: Wed 三 | I9: Thu 四 | J9: Fri 五 | K9: Sat 六
A10: Exact Location: 正確地點 | D10: =Data!B5 -> 0
B11: at 在 | C11: Junction with 下述街道交界處 __________________________________________________________________________________________________________________________________
B12: near 近著
A13: Time 時間 | B13: EHT staff arriving scene 隧道職員到達 | H13: =Data!B6 -> 0 | I13: 時 | J13: EHT staff leavng scene 隧道職員離開 | N13: =Data!B7 -> 0 | O13: 時
B14: HKP/ AIS staff arriving scene 警察意外調查組到達 | H14: =Data!E5 -> 0 | I14: 時 | J14: HKP/AIS staff leaving scene 警察意外調查組離開 | N14: =Data!E6 -> 0 | O14: 時
A15: 2. CONDITION AT SCENE 現場情況
A16: Weather 天氣 | D16: Lighting 光線 | J16: Traffic 交通 | L16: 行車道 Roadway | N16: 行人道Footpath
B17: Fine 良好 | J17: Heavy 擠塞
E18: Day light 日間 | J18: Medium 普通
B19: Dull 陰暗 | E19: Dawn 黎明 | G19: Dusk 黃昏 | I19: Dark 夜間 | J19: Light 暢通
J20: State of Surface 路面情況
B21: Mist 薄霧 | D21: Street Lighting 街燈情況 | J21: Wet 濕
J22: Dry 乾
B23: Strong Wind 強風 | E23: Good 燈光明亮 | H23: Obscured 街燈受遮 | J23: In good repair 完整
J24: Slippery 滑溜
B25: Rain - light 微雨 | E25: Poor (Or None) | H25: Not Lit | J25: Potholes 有凹孔
E26: 燈光微弱（或無燈光） | H26: 街燈未亮 | J26: Mud / Sand 泥／沙
B27: Rain - heavy 大雨 | J27: Unreinstated Trench 渠溝未修妥
A28: 3. VEHICLE INVOLVED 有關車輛 | G28: V1 | I28: DRIVER INVOLVED 有關司機 | O28: D1
A29: Vehicle Registration Number 車輛登記號碼 | E29: Class 類別 | I29: Driver's Name 司機姓名 | N29: Age 年齡
I30: Mr | J30: =Data!E12 -> 0 | M30: 先生 | N30: =Data!E14 -> 0
A31: =Data!B12 -> 0 | E31: =Data!B13 -> 0 | I31: Mrs. | J31: =Data!E13 -> 0 | M31: 夫人
I32: Miss. | M32: 小姐
A33: Make 廠名 | E33: Colour 顏色 | I33: Address 住址 | J33: =Data!E15 -> 0
A34: =Data!B14 -> 0 | E34: =Data!B15 -> 0 | I34: =Data!E16 -> 0
I35: Tel. No. 電話號碼 | L35: Identity Card Number 身份證號碼
A36: Vehicle Insurance 車輛保險 | B36: Policy No. 保單號碼 | E36: Expiry Date 期滿日期 | I36: =Data!E17 -> 0 | L36: =Data!E18 -> 0
I37: Driver's Licence Number 駕駛執照號碼 | M37: Class 類別
A38: Insurers 保險公司 | E38: Comprehensive 全保 | I38: =Data!E19 -> 0 | M38: =Data!E20 -> 0
E39: Third party 第三者保險 | I39: Expiry Date: 期滿日期 | L39: Licence Conitions (if any) 執照所載規條 (如有任何規條者)
A40: Vehicle Licence Number 車輛牌照號碼 | D40: Expiry Date 期滿日期 | G40: Seating Capacity 車輛載客額 | I40: =Data!E21 -> 0 | L40: =Data!E22 -> 0
A41: =Data!B16 -> 0 | D41: =Data!B17 -> 0 | G41: =Data!B18 -> 0
A43: Load (Goods Vehicle) (貨車) 所載貨物 | G43: No. of passengers carried 事發時乘客數目
...

Sheet P.2
A1: 4. VEHICLE INVOLVED 有關車輛 | G1: V2 | H1: DRIVER INVOLVED 有關司機 | O1: D2
A2: Vehicle Registration Number 車輛登記號碼 | E2: Class 類別 | H2: Driver's Name 司機姓名 | N2: Age 年齡
I3: Mr | J3: =Data!E27 -> 0 | M3: 先生 | N3: =Data!E29 -> 0
A4: =Data!B27 -> 0 | E4: =Data!B28 -> 0 | I4: Mrs. | J4: =Data!E28 -> 0 | M4: 夫人
I5: Miss. | M5: 小姐
A6: Make 廠名 | E6: Colour 顏色 | H6: Address 住址 | J6: =Data!E30 -> 0
A7: =Data!B29 -> 0 | E7: =Data!B30 -> 0 | H7: =Data!E31 -> 0
H8: Tel. No. 電話號碼 | L8: Identity Card Number 身份證號碼
A9: Vehicle Insurance 車輛保險 | B9: Policy No. 保單號碼 | E9: Expiry Date 期滿日期 | H9: =Data!E32 -> 0 | L9: =Data!E33 -> 0
H10: Driver's Licence Number 駕駛執照號碼 | L10: Class 類別
A11: Insurers 保險公司 | E11: Comprehensive 全保 | H11: =Data!E34 -> 0 | L11: =Data!E35 -> 0
E12: Third party 第三者保險 | H12: Expiry Date: 期滿日期 | L12: Licence Conditions (if any) 執照所載規條 (如有任何規條者)
A13: Vehicle Licence Number 車輛牌照號碼 | D13: Expiry Date 期滿日期 | F13: Seating Capacity 車輛載客額 | H13: =Data!E36 -> 0 | L13: =Data!E37 -> 0
A14: =Data!B31 -> 0 | D14: ------- | F14: =Data!B33 -> 0
A16: Load (Goods Vehicle) (貨車) 所載貨物 | F16: No. of passengers carried 事發時乘客數目
B17: None 無 | D17: Secure 繫穩 | E17: Insecure 未繫穩 | F17: =Data!B19 -> 0
A18: Condition of tyres 車胎情況 | E18: normal 正常 | G18: smooth 光滑
A19: Nature and Severity of Damage 損毀性質及程度
A20: =Data!B35 -> 0
A23: Vehicle defects alleged 車輛疑有毛病 | E23: yes 是 | G23: no 否
A24: Nature of defect 毛病之性質
A25: By whom 何人懷疑
A26: 5. VEHICLE INVOLVED 有關車輛 | G26: V3 | H26: DRIVER INVOLVED 有關司機 | O26: D3
A27: Vehicle Registration Number 車輛登記號碼 | E27: Class 類別 | H27: Driver's Name 司機姓名 | N27: Age 年齡
I28: Mr | J28: =Data!E43 -> 0 | M28: 先生 | N28: =Data!E45 -> 0
A29: =Data!B43 -> 0 | E29: =Data!B44 -> 0 | I29: Mrs. | J29: =Data!E44 -> 0 | M29: 夫人
I30: Miss. | M30: 小姐
A31: Make 廠名 | E31: Colour 顏色 | H31: Address 住址 | J31: =Data!E46 -> 0
A32: =Data!B45 -> 0 | E32: =Data!B46 -> 0 | H32: =Data!E47 -> 0
H33: Tel. No. 電話號碼 | L33: Identity Card Number 身份証號碼
A34: Vehicle Insurance 車輛保險 | B34: Policy No. 保單號碼 | E34: Expiry Date 期滿日期 | H34: =Data!E48 -> 0 | L34: =Data!E49 -> 0
H35: Driver's Licence Number 駕駛執照號碼 | L35: Class 類別
A36: Insurers 保險公司 | E36: Comprehensive 全保 | H36: =Data!E50 -> 0 | L36: =Data!E51 -> 0
E37: Third party 第三者保險 | H37: Expiry Date: 期滿日期 | L37: Licence Conditions (if any) 執照所載規條 (如有任何規條者)
A38: Vehicle Licence Number 車輛牌照號碼 | D38: Expiry Date 期滿日期 | F38: Seating Capacity 車輛載客額 4 | H38: =Data!E52 -> 0 | L38: =Data!E53 -> 0
A39: =Data!B47 -> 0 | D39: =Data!B48 -> 0 | F39: =Data!B49 -> 0
A41: Load (Goods Vehicle) (貨車) 所載貨物 | F41: No. of passengers carried 事發時乘客數目
B42: None 無 | D42: Secure 繫穩 | E42: Insecure 未繫穩 | F42: =Data!B50 -> 0
A43: Condition of tyres 車胎情況 | D43: normal 正常 | G43: smooth 光滑
A44: Nature and Severity of Damage 損毀性質及程度
...

Sheet P.3
A1: 6. VEHICLE INVOLVED 有關車輛 | G1: V4 | H1: DRIVER INVOLVED 有關司機 | O1: D4
A2: Vehicle Registration Number 車輛登記號碼 | E2: Class 類別 | H2: Driver's Name 司機姓名 | N2: Age 年齡
I3: Mr | J3: =Data!E58 -> 0 | M3: 先生 | N3: =Data!E60 -> 0
A4: =Data!B58 -> 0 | E4: =Data!B59 -> 0 | I4: Mrs. | J4: =Data!E59 -> 0 | M4: 夫人
I5: Miss. | M5: 小姐
A6: Make 廠名 | E6: Colour 顏色 | H6: Address 住址 | J6: =Data!E61 -> 0
A7: =Data!B60 -> 0 | E7: =Data!B61 -> 0 | H7: =Data!E62 -> 0
H8: Tel. No. 電話號碼 | L8: Identity Card Number 身份證號碼
A9: Vehicle Insurance 車輛保險 | B9: Policy No. 保單號碼 | E9: Expiry Date 期滿日期 | H9: =Data!E63 -> 0 | L9: =Data!E64 -> 0
H10: Driver's Licence Number 駕駛執照號碼 | L10: Class 類別
A11: Insurers 保險公司 | E11: Comprehensive 全保 | H11: =Data!E65 -> 0 | L11: =Data!E66 -> 0
E12: Third party 第三者保險 | H12: Expiry Date: 期滿日期 | L12: Licence Conditions (if any) 執照所載規條 (如有任何規條者)
A13: Vehicle Licence Number 車輛牌照號碼 | D13: Expiry Date 期滿日期 | G13: Seating Capacity 車輛載客額 | H13: =Data!E67 -> 0 | L13: =Data!E68 -> 0
A14: =Data!B62 -> 0 | D14: =Data!B63 -> 0 | G14: =Data!B64 -> 0
A16: Load (Goods Vehicle) (貨車) 所載貨物 | G16: No. of passengers carried 事發時乘客數目
B17: None 無 | D17: Secure 繫穩 | F17: Insecure 未繫穩 | G17: =Data!B65 -> 0
A18: Condition of tyres 車胎情況 | D18: normal 正常 | G18: smooth 光滑
A19: Nature and Severity of Damage 損毀性質及程度
A20: =Data!B66 -> 0
A23: Vehicle defects alleged 車輛疑有毛病 | E23: yes 是 | G23: no 否
A24: Nature of defect 毛病之性質
A25: By whom 何人懷疑
A26: 7. INJURED PERSONS: Total number involved 受傷者: | H26: 共 | I26: =Data!B74 -> 0 | J26: 人
A27: 1. | B27: Name 姓名 | G27: Age 年齡 | H27: 2. | I27: Name 姓名 | N27: Age 年齡
B28: Mr. | D28: =Data!B77 -> 0 | F28: 先生 | G28: =Data!B79 -> 0 | I28: Mr. | J28: =Data!E77 -> 0 | M28: 先生 | N28: =Data!E79 -> 0
B29: Mrs. | D29: =Data!B78 -> 0 | F29: 夫人 | I29: Mrs. | J29: =Data!E78 -> 0 | M29: 夫人
B30: Miss | F30: 小姐 | I30: Miss | M30: 小姐
A31: Address 地址 | C31: =Data!B80 -> 0 | G31: Tel No. 電話號碼 | H31: Address 地址 | J31: =Data!E80 -> 0 | N31: Tel No. 電話號碼
A32: =Data!B81 -> 0 | G32: =Data!B82 -> 0 | H32: =Data!E81 -> 0 | N32: =Data!E82 -> 0
A34: Injured person is a 受傷者為 | G34: Vehicle Number 車牌號碼 | H34: Injured person is a 受傷者為 | N34: Vehicle Number 車牌號碼
B35: driver 司機 | C35: passenger 乘客 | E35: pedestrian 行人 | G35: =Data!B83 -> 0 | I35: driver 司機 | J35: passenger 乘客 | L35: pedestrian 行人 | N35: =Data!E83 -> 0
A36: Taken to 已送往 | B36: =Data!B84 -> 0 | E36: Hospital 醫院 | F36: Admitted 留醫 | H36: Taken to 已送往 | I36: =Data!E84 -> 0 | L36: Hospital 醫院 | N36: Admitted 留醫
A38: Escorted by 護送人 | D38: =Data!B85 -> 0 | F38: Discharged 無需留醫 | H38: Escorted by 護送人 | K38: =Data!E85 -> 0 | N38: Discharged 無需留醫
A39: 3. | B39: Name 姓名 | G39: Age 年齡 | H39: 4. | I39: Name 姓名 | N39: Age 年齡
B40: Mr. | D40: =Data!B89 -> 0 | F40: 先生 | G40: =Data!B91 -> 0 | I40: Mr. | J40: =Data!E89 -> 0 | M40: 先生 | N40: =Data!E91 -> 0
B41: Mrs. | D41: =Data!B90 -> 0 | F41: 夫人 | I41: Mrs. | J41: =Data!E90 -> 0 | M41: 夫人
B42: Miss | F42: 小姐 | I42: Miss | M42: 小姐
A43: Address 地址 | C43: =Data!B92 -> 0 | G43: Tel No. 電話號碼 | H43: Address 地址 | J43: =Data!E92 -> 0 | N43: Tel No. 電話號碼
A44: =Data!B93 -> 0 | G44: =Data!B94 -> 0 | H44: =Data!E93 -> 0 | N44: =Data!E94 -> 0
A46: Injured person is a 受傷者為 | G46: Vehicle Number 車牌號碼 | H46: Injured person is a 受傷者為 | N46: Vehicle Number 車牌號碼
...

Sheet P.4
A1: 5. | B1: Name 姓名 | G1: Age 年齡 | H1: 6. | I1: Name 姓名 | N1: Age 年齡
B2: Mr. | F2: 先生 | J2: Mr. | L2: 先生
B3: Mrs. | F3: 夫人 | J3: Mrs. | L3: 夫人
B4: Miss | F4: 小姐 | J4: Miss | L4: 小姐
A5: Address 地址 | G5: Tel No. 電話號碼 | H5: Address 地址 | N5: Tel No. 電話號碼
A8: Injured person is a 受傷者為 | G8: Vehicle Number 車牌號碼 | H8: Injured person is a 受傷者為 | N8: Vehicle Number 車牌號碼
B9: driver 司機 | C9: passenger 乘客 | E9: pedestrian 行人 | I9: driver 司機 | J9: passenger 乘客 | L9: pedestrian 行人
A10: Taken to 已送往 | E10: Hospital 醫院 | F10: Admitted 留醫 | H10: Taken to 已送往 | L10: Hospital 醫院 | M10: Admitted 留醫
A12: Escorted by 護送人 | F12: Discharged 無需留醫 | H12: Escorted by 護送人 | M12: Discharged 無需留醫
A13: 8. MISCELLANEOUS INFORMATION 雜項報告
A14: Vehicle(s) at the scene on arrival 到達現場時是否目睹車輛 | E14: Position chalk marked 位置已否用粉筆畫明 | H14: Chalk marked by 由何人用粉筆畫明
B15: yes 是 | D15: no 否 | F15: yes 是 | G15: no 否
A16: Injured person(s) at the scene on arrival 到達現場時有否目睹傷者 | E16: Position chalk marked 位置已否用粉筆畫明 | H16: Chalk marked by 由何人用粉筆畫明
B17: yes 是 | D17: no 否 | F17: yes 是 | G17: no 否
A18: Photograph taken by 負責拍攝照片者 | C18: OS 155 | G18: of 有關失事之
I19: in position 車輛在原有位置 | M19: not in position 車輛並非在原有位置
B20: Vehicle(s) 車輛 | D20: Person(s) 人 | F20: Scene 現場
A21: Contact Evidence 失事現場
A22: Items found at the scene which might be useful as exhibits 在現場發現可用作證物之物件
B23: Blood stains 血漬 | G23: Hair 毛髮 | J23: Glass 玻璃 | M23: Paint scrapings 油漆碎屑
B24: Skid marks 車輛滑行痕跡 | G24: Clothing 衣物 | J24: Other specify 其他詳情
A25: 9. WITNESSES 證人
A26: 1. | B26: Name 姓名 | G26: Age 年齡 | H26: 2. | I26: Name 姓名 | N26: Age 年齡
B27: Mr. | E27: 先生 | J27: Mr. | L27: 先生
B28: Mrs. | E28: 夫人 | J28: Mrs. | L28: 夫人
B29: Miss | E29: 小姐 | J29: Miss | L29: 小姐
A30: Address 地址 | G30: Tel No. 電話號碼 | H30: Address 地址 | N30: Tel No. 電話號碼
A33: In vehicle (if yes, specify vehicle number) | H33: In vehicle (if yes, specify vehicle number)
A34: 是否在車內 (若是則註明汽車號碼 ) | H34: 是否在車內 (若是則註明汽車號碼 )
B35: yes 是 | D35: no 否 | E35: Vehicle No. 汽車號碼 | I35: yes 是 | K35: no 否 | L35: Vehicle No. 汽車號碼
A36: 10. PROPERTY DAMAGED (other than vehicles involved) 損毀之財物 (有關車輛除外 )
N38: Serial No.
A39: 11. DATE OF ARRIVAL OF POLICE 09-07-2026 TIME 2205 hrs. RANK SPC NO. 51653 STATION HKI AIS/ PC60532 | E39: =M49 -> 0 | G39: TIME: | H39: =Data!E2 -> 0 | I39: Hrs | K39: Rank: | L39: SPC | M39: No: | N39: =Data!E3 -> 0
G40: Station | H40: TPE | K40: AIS/ | L40: SPC | M40: No: | N40: =Data!E4 -> 0
A41: 12. INJURED PERSONS BELONGINGS HANDED OVER TO A POLICE OFFICER.
A44: I HAVE RECEIVED THE ABOVE ITEMS
K45: SIGNATIRE__________________________
K46: RANK & NAME OR NO._______________
A47: 13. OFFICER COMPLETING REPORT 填寫報告之人員
A48: RANK | C48: NUMBER | E48: NAME | I48: SIGNATURE | M48: DATE
...

Sheet Police
A1: HKI | D1: PC
A2: TPE | D2: SPC
D3: SGT

Sheet  Staff
A1: OS 155 | F1: OS | G1: 155 | H1: Lee Kam Chuen
A2: OS 179 | F2: A/OS | G2: 179 | H2: Leung Chun Shing
A3: OS 189 | F3: TO | G3: 189 | H3: Wong Yam Kwong
A4: OS 917 | G4: 917 | H4: Yung Wai Leung
A5: OS 195 | G5: 195 | H5: Lo Man Chi
